Workbook

Sheet YouTube Feature List
A1: MundiVeo — YouTube Feature Inventory & MVP Prioritization (MoSCoW)
A2: Every project member: fill in the 'MVP Priority' column per row. Compiled from current YouTube features plus notable historical/removed features (marked 'Legacy'). Not exhaustive of every minor UI tweak — focused on decision-worthy functionality.
A4: # | B4: Segment | C4: Feature / Function | D4: Description | E4: Status | F4: MVP Priority | G4: Notes / Rationale
A5: 1 | B5: 1. Account & Onboarding | C5: Single sign-on account | D5: One account (originally Google-linked) used to access the whole platform | E5: Current
A6: 2 | B6: 1. Account & Onboarding | C6: Custom @handle | D6: Unique, human-readable username separate from display name | E6: Current | G6: Introduced 2022
A7: 3 | B7: 1. Account & Onboarding | C7: Channel creation wizard | D7: Guided first-time setup flow for a new channel | E7: Current
A8: 4 | B8: 1. Account & Onboarding | C8: Profile picture & banner art | D8: Visual branding elements on the channel page | E8: Current
A9: 5 | B9: 1. Account & Onboarding | C9: Verification badge | D9: Checkmark shown once a channel passes a subscriber/identity threshold | E9: Current
A10: 6 | B10: 1. Account & Onboarding | C10: Multiple channels per account | D10: Manage several channels (e.g. brand accounts) under one login | E10: Current
A11: 7 | B11: 1. Account & Onboarding | C11: Two-factor authentication | D11: Extra login security step | E11: Current
A12: 8 | B12: 1. Account & Onboarding | C12: Account recovery flow | D12: Regain access via phone/email if locked out | E12: Current
A13: 9 | B13: 1. Account & Onboarding | C13: Channel trailer for non-subscribers | D13: Auto-played intro video shown only to people not yet subscribed | E13: Current
A14: 10 | B14: 1. Account & Onboarding | C14: Social links on channel | D14: Outbound links to other platforms shown on the About page | E14: Current
A15: 11 | B15: 2. Upload & Video Management | C15: Standard video upload | D15: Browser/app-based upload of a video file | E15: Current
A16: 12 | B16: 2. Upload & Video Management | C16: Bulk/batch upload | D16: Upload multiple videos in one session | E16: Current
A17: 13 | B17: 2. Upload & Video Management | C17: Privacy settings (Public/Unlisted/Private/Scheduled) | D17: Control who can find and view a video, or delay publishing | E17: Current
A18: 14 | B18: 2. Upload & Video Management | C18: Custom thumbnail upload | D18: Creator-chosen still image representing the video | E18: Current
... A22: 18 | B22: 2. Upload & Video Management | C22: Auto-detected chapters (AI) | D22: Platform automatically segments a video into chapters | E22: Current
A23: 19 | B23: 2. Upload & Video Management | C23: End screens | D23: Clickable subscribe/video/playlist links shown in the last ~20 seconds | E23: Current | G23: Replaced annotations, 2017+
A24: 20 | B24: 2. Upload & Video Management | C24: Cards | D24: Small clickable overlays (link, poll, merchandise) shown during playback | E24: Current | G24: Replaced annotations, 2017+
A25: 21 | B25: 2. Upload & Video Management | C25: Pop-up annotations | D25: Clickable text/image overlays drawn anywhere on the video frame | E25: Legacy - Removed | G25: Editor removed 2017-2018, all annotations deleted Jan 2019
A26: 22 | B26: 2. Upload & Video Management | C26: Caption/subtitle file upload | D26: Creator-supplied closed caption track | E26: Current
A27: 23 | B27: 2. Upload & Video Management | C27: Auto-dubbing into other languages (AI) | D27: Automatic AI-generated dubbed audio tracks, now free for all eligible creators | E27: Current | G27: Rolled out to all creators 2025-2026, 27 languages
A28: 24 | B28: 2. Upload & Video Management | C28: Creator-supplied dub audio tracks | D28: Manually uploaded alternate-language audio track | E28: Current
A29: 25 | B29: 2. Upload & Video Management | C29: Made-for-Kids toggle | D29: Legal/COPPA-style content classification at upload | E29: Current
A30: 26 | B30: 2. Upload & Video Management | C30: Built-in basic video editor | D30: In-browser trim, blur, audio swap, filters | E30: Current
A31: 27 | B31: 2. Upload & Video Management | C31: Automated copyright scan on upload | D31: Content ID check before/at publishing | E31: Current
A32: 28 | B32: 2. Upload & Video Management | C32: Scheduled premieres | D32: Video goes live at a set time with a countdown and live chat | E32: Current
A33: 29 | B33: 2. Upload & Video Management | C33: Replace uploaded video file | D33: Swap the underlying file while keeping URL/stats/comments | E33: Current
A34: 30 | B34: 2. Upload & Video Management | C34: Playlist creation & management | D34: Group videos into ordered or shuffled collections | E34: Current
A35: 31 | B35: 2. Upload & Video Management | C35: Series/season grouping | D35: Structure playlists as episodic seasons | E35: Current
A36: 32 | B36: 3. Video Player & Playback | C36: Adaptive-resolution streaming | D36: Automatic quality adjustment based on connection (144p-8K) | E36: Current
A37: 33 | B37: 3. Video Player & Playback | C37: Manual resolution selection | D37: Viewer overrides the automatic quality choice | E37: Current
A38: 34 | B38: 3. Video Player & Playback | C38: Playback speed control | D38: 0.25x-2x (or custom) speed adjustment | E38: Current
A39: 35 | B39: 3. Video Player & Playback | C39: Picture-in-picture / mini-player | D39: Keep watching in a small floating window while browsing | E39: Current
... A50: 46 | B50: 3. Video Player & Playback | C50: HDR playback | D50: High dynamic range video support | E50: Current
A51: 47 | B51: 3. Video Player & Playback | C51: Multi-camera / multiview live playback | D51: Watch multiple camera angles or streams at once (e.g. live sports) | E51: Current | G51: Expanding on YouTube TV, 2026
A52: 48 | B52: 3. Video Player & Playback | C52: Five-star rating system | D52: Rate a video 1-5 stars | E52: Legacy - Removed | G52: Replaced by like/dislike, 2009-2010
A53: 49 | B53: 3. Video Player & Playback | C53: Like / Dislike buttons | D53: Simple binary feedback on a video | E53: Current
A54: 50 | B54: 3. Video Player & Playback | C54: Public dislike counter | D54: Dislike count visible to all viewers, not just the creator | E54: Legacy - Removed | G54: Hidden from public view, Nov 2021
...

Sheet Instructions
A1: MundiVeo — How to use this spreadsheet
A3: Goal: decide which YouTube-style features MundiVeo's MVP should launch with, before the platform is public and everyone starts requesting things.
A5: The MoSCoW method:
A6: MUST HAVE — the MVP is not viable without this. Launch blocker.
A7: SHOULD HAVE — important, but the MVP can technically launch without it for a short time.
A8: COULD HAVE — nice, adds polish, first to be cut if time/budget is tight.
A9: WON'T HAVE (this round) — deliberately excluded from this phase. Can be revisited later (including via community governance vote).
A10: NEEDS DISCUSSION — reasonable people disagree, or it needs more information (legal, cost, technical) before deciding.
A12: How to vote:
A13: 1. Go to the 'YouTube Feature List' tab.
A14: 2. For every row, use the dropdown in the 'MVP Priority' column to pick your preferred option.
A15: 3. Use the 'Notes / Rationale' column (or add your own name in brackets) to explain your reasoning, especially for anything you'd mark WON'T HAVE.
... A19: Note: this list focuses on decision-worthy functionality, not every minor UI tweak. If you spot something important missing, add a new row in the correct segment rather than starting a new list.

Sheet Summary Dashboard
A1: Summary Dashboard — auto-updates as the team fills in MVP Priority
A3: Segment | B3: MUST HAVE | C3: SHOULD HAVE | D3: COULD HAVE | E3: WON'T HAVE (this round) | F3: NEEDS DISCUSSION | G3: Total rows
A4: 1. Account & Onboarding | B4: =COUNTIFS('YouTube Feature List'!$B5:$B189,$A4,'YouTube Feature List'!$F5:$F189,B$3) -> 0 | C4: =COUNTIFS('YouTube Feature List'!$B5:$B189,$A4,'YouTube Feature List'!$F5:$F189,C$3) -> 0 | D4: =COUNTIFS('YouTube Feature List'!$B5:$B189,$A4,'YouTube Feature List'!$F5:$F189,D$3) -> 0 | E4: =COUNTIFS('YouTube Feature List'!$B5:$B189,$A4,'YouTube Feature List'!$F5:$F189,E$3) -> 0 | F4: =COUNTIFS('YouTube Feature List'!$B5:$B189,$A4,'YouTube Feature List'!$F5:$F189,F$3) -> 0 | G4: =COUNTIF('YouTube Feature List'!$B5:$B189,$A4) -> 10
A5: 2. Upload & Video Management | B5: =COUNTIFS('YouTube Feature List'!$B5:$B189,$A5,'YouTube Feature List'!$F5:$F189,B$3) -> 0 | C5: =COUNTIFS('YouTube Feature List'!$B5:$B189,$A5,'YouTube Feature List'!$F5:$F189,C$3) -> 0 | D5: =COUNTIFS('YouTube Feature List'!$B5:$B189,$A5,'YouTube Feature List'!$F5:$F189,D$3) -> 0 | E5: =COUNTIFS('YouTube Feature List'!$B5:$B189,$A5,'YouTube Feature List'!$F5:$F189,E$3) -> 0 | F5: =COUNTIFS('YouTube Feature List'!$B5:$B189,$A5,'YouTube Feature List'!$F5:$F189,F$3) -> 0 | G5: =COUNTIF('YouTube Feature List'!$B5:$B189,$A5) -> 21
A6: 3. Video Player & Playback | B6: =COUNTIFS('YouTube Feature List'!$B5:$B189,$A6,'YouTube Feature List'!$F5:$F189,B$3) -> 0 | C6: =COUNTIFS('YouTube Feature List'!$B5:$B189,$A6,'YouTube Feature List'!$F5:$F189,C$3) -> 0 | D6: =COUNTIFS('YouTube Feature List'!$B5:$B189,$A6,'YouTube Feature List'!$F5:$F189,D$3) -> 0 | E6: =COUNTIFS('YouTube Feature List'!$B5:$B189,$A6,'YouTube Feature List'!$F5:$F189,E$3) -> 0 | F6: =COUNTIFS('YouTube Feature List'!$B5:$B189,$A6,'YouTube Feature List'!$F5:$F189,F$3) -> 0 | G6: =COUNTIF('YouTube Feature List'!$B5:$B189,$A6) -> 20
A7: 4. Discovery, Search & Recommendations | B7: =COUNTIFS('YouTube Feature List'!$B5:$B189,$A7,'YouTube Feature List'!$F5:$F189,B$3) -> 0 | C7: =COUNTIFS('YouTube Feature List'!$B5:$B189,$A7,'YouTube Feature List'!$F5:$F189,C$3) -> 0 | D7: =COUNTIFS('YouTube Feature List'!$B5:$B189,$A7,'YouTube Feature List'!$F5:$F189,D$3) -> 0 | E7: =COUNTIFS('YouTube Feature List'!$B5:$B189,$A7,'YouTube Feature List'!$F5:$F189,E$3) -> 0 | F7: =COUNTIFS('YouTube Feature List'!$B5:$B189,$A7,'YouTube Feature List'!$F5:$F189,F$3) -> 0 | G7: =COUNTIF('YouTube Feature List'!$B5:$B189,$A7) -> 14
A8: 5. Channel Page & Branding | B8: =COUNTIFS('YouTube Feature List'!$B5:$B189,$A8,'YouTube Feature List'!$F5:$F189,B$3) -> 0 | C8: =COUNTIFS('YouTube Feature List'!$B5:$B189,$A8,'YouTube Feature List'!$F5:$F189,C$3) -> 0 | D8: =COUNTIFS('YouTube Feature List'!$B5:$B189,$A8,'YouTube Feature List'!$F5:$F189,D$3) -> 0 | E8: =COUNTIFS('YouTube Feature List'!$B5:$B189,$A8,'YouTube Feature List'!$F5:$F189,E$3) -> 0 | F8: =COUNTIFS('YouTube Feature List'!$B5:$B189,$A8,'YouTube Feature List'!$F5:$F189,F$3) -> 0 | G8: =COUNTIF('YouTube Feature List'!$B5:$B189,$A8) -> 9
A9: 6. Comments & Engagement | B9: =COUNTIFS('YouTube Feature List'!$B5:$B189,$A9,'YouTube Feature List'!$F5:$F189,B$3) -> 0 | C9: =COUNTIFS('YouTube Feature List'!$B5:$B189,$A9,'YouTube Feature List'!$F5:$F189,C$3) -> 0 | D9: =COUNTIFS('YouTube Feature List'!$B5:$B189,$A9,'YouTube Feature List'!$F5:$F189,D$3) -> 0 | E9: =COUNTIFS('YouTube Feature List'!$B5:$B189,$A9,'YouTube Feature List'!$F5:$F189,E$3) -> 0 | F9: =COUNTIFS('YouTube Feature List'!$B5:$B189,$A9,'YouTube Feature List'!$F5:$F189,F$3) -> 0 | G9: =COUNTIF('YouTube Feature List'!$B5:$B189,$A9) -> 11
A10: 7. Community Tab / Posts | B10: =COUNTIFS('YouTube Feature List'!$B5:$B189,$A10,'YouTube Feature List'!$F5:$F189,B$3) -> 0 | C10: =COUNTIFS('YouTube Feature List'!$B5:$B189,$A10,'YouTube Feature List'!$F5:$F189,C$3) -> 0 | D10: =COUNTIFS('YouTube Feature List'!$B5:$B189,$A10,'YouTube Feature List'!$F5:$F189,D$3) -> 0 | E10: =COUNTIFS('YouTube Feature List'!$B5:$B189,$A10,'YouTube Feature List'!$F5:$F189,E$3) -> 0 | F10: =COUNTIFS('YouTube Feature List'!$B5:$B189,$A10,'YouTube Feature List'!$F5:$F189,F$3) -> 0 | G10: =COUNTIF('YouTube Feature List'!$B5:$B189,$A10) -> 7
A11: 8. Live Streaming | B11: =COUNTIFS('YouTube Feature List'!$B5:$B189,$A11,'YouTube Feature List'!$F5:$F189,B$3) -> 0 | C11: =COUNTIFS('YouTube Feature List'!$B5:$B189,$A11,'YouTube Feature List'!$F5:$F189,C$3) -> 0 | D11: =COUNTIFS('YouTube Feature List'!$B5:$B189,$A11,'YouTube Feature List'!$F5:$F189,D$3) -> 0 | E11: =COUNTIFS('YouTube Feature List'!$B5:$B189,$A11,'YouTube Feature List'!$F5:$F189,E$3) -> 0 | F11: =COUNTIFS('YouTube Feature List'!$B5:$B189,$A11,'YouTube Feature List'!$F5:$F189,F$3) -> 0 | G11: =COUNTIF('YouTube Feature List'!$B5:$B189,$A11) -> 11
A12: 9. Shorts (Short-form Video) | B12: =COUNTIFS('YouTube Feature List'!$B5:$B189,$A12,'YouTube Feature List'!$F5:$F189,B$3) -> 0 | C12: =COUNTIFS('YouTube Feature List'!$B5:$B189,$A12,'YouTube Feature List'!$F5:$F189,C$3) -> 0 | D12: =COUNTIFS('YouTube Feature List'!$B5:$B189,$A12,'YouTube Feature List'!$F5:$F189,D$3) -> 0 | E12: =COUNTIFS('YouTube Feature List'!$B5:$B189,$A12,'YouTube Feature List'!$F5:$F189,E$3) -> 0 | F12: =COUNTIFS('YouTube Feature List'!$B5:$B189,$A12,'YouTube Feature List'!$F5:$F189,F$3) -> 0 | G12: =COUNTIF('YouTube Feature List'!$B5:$B189,$A12) -> 11
A13: 10. Notifications & Subscriptions | B13: =COUNTIFS('YouTube Feature List'!$B5:$B189,$A13,'YouTube Feature List'!$F5:$F189,B$3) -> 0 | C13: =COUNTIFS('YouTube Feature List'!$B5:$B189,$A13,'YouTube Feature List'!$F5:$F189,C$3) -> 0 | D13: =COUNTIFS('YouTube Feature List'!$B5:$B189,$A13,'YouTube Feature List'!$F5:$F189,D$3) -> 0 | E13: =COUNTIFS('YouTube Feature List'!$B5:$B189,$A13,'YouTube Feature List'!$F5:$F189,E$3) -> 0 | F13: =COUNTIFS('YouTube Feature List'!$B5:$B189,$A13,'YouTube Feature List'!$F5:$F189,F$3) -> 0 | G13: =COUNTIF('YouTube Feature List'!$B5:$B189,$A13) -> 6
A14: 11. Monetization & Creator Revenue | B14: =COUNTIFS('YouTube Feature List'!$B5:$B189,$A14,'YouTube Feature List'!$F5:$F189,B$3) -> 0 | C14: =COUNTIFS('YouTube Feature List'!$B5:$B189,$A14,'YouTube Feature List'!$F5:$F189,C$3) -> 0 | D14: =COUNTIFS('YouTube Feature List'!$B5:$B189,$A14,'YouTube Feature List'!$F5:$F189,D$3) -> 0 | E14: =COUNTIFS('YouTube Feature List'!$B5:$B189,$A14,'YouTube Feature List'!$F5:$F189,E$3) -> 0 | F14: =COUNTIFS('YouTube Feature List'!$B5:$B189,$A14,'YouTube Feature List'!$F5:$F189,F$3) -> 0 | G14: =COUNTIF('YouTube Feature List'!$B5:$B189,$A14) -> 14
A15: 12. Creator Studio & Analytics | B15: =COUNTIFS('YouTube Feature List'!$B5:$B189,$A15,'YouTube Feature List'!$F5:$F189,B$3) -> 0 | C15: =COUNTIFS('YouTube Feature List'!$B5:$B189,$A15,'YouTube Feature List'!$F5:$F189,C$3) -> 0 | D15: =COUNTIFS('YouTube Feature List'!$B5:$B189,$A15,'YouTube Feature List'!$F5:$F189,D$3) -> 0 | E15: =COUNTIFS('YouTube Feature List'!$B5:$B189,$A15,'YouTube Feature List'!$F5:$F189,E$3) -> 0 | F15: =COUNTIFS('YouTube Feature List'!$B5:$B189,$A15,'YouTube Feature List'!$F5:$F189,F$3) -> 0 | G15: =COUNTIF('YouTube Feature List'!$B5:$B189,$A15) -> 12
A16: 13. Moderation, Safety & Trust | B16: =COUNTIFS('YouTube Feature List'!$B5:$B189,$A16,'YouTube Feature List'!$F5:$F189,B$3) -> 0 | C16: =COUNTIFS('YouTube Feature List'!$B5:$B189,$A16,'YouTube Feature List'!$F5:$F189,C$3) -> 0 | D16: =COUNTIFS('YouTube Feature List'!$B5:$B189,$A16,'YouTube Feature List'!$F5:$F189,D$3) -> 0 | E16: =COUNTIFS('YouTube Feature List'!$B5:$B189,$A16,'YouTube Feature List'!$F5:$F189,E$3) -> 0 | F16: =COUNTIFS('YouTube Feature List'!$B5:$B189,$A16,'YouTube Feature List'!$F5:$F189,F$3) -> 0 | G16: =COUNTIF('YouTube Feature List'!$B5:$B189,$A16) -> 11
A17: 14. Accessibility & Localization | B17: =COUNTIFS('YouTube Feature List'!$B5:$B189,$A17,'YouTube Feature List'!$F5:$F189,B$3) -> 0 | C17: =COUNTIFS('YouTube Feature List'!$B5:$B189,$A17,'YouTube Feature List'!$F5:$F189,C$3) -> 0 | D17: =COUNTIFS('YouTube Feature List'!$B5:$B189,$A17,'YouTube Feature List'!$F5:$F189,D$3) -> 0 | E17: =COUNTIFS('YouTube Feature List'!$B5:$B189,$A17,'YouTube Feature List'!$F5:$F189,E$3) -> 0 | F17: =COUNTIFS('YouTube Feature List'!$B5:$B189,$A17,'YouTube Feature List'!$F5:$F189,F$3) -> 0 | G17: =COUNTIF('YouTube Feature List'!$B5:$B189,$A17) -> 6
A18: 15. Kids & Family Safety | B18: =COUNTIFS('YouTube Feature List'!$B5:$B189,$A18,'YouTube Feature List'!$F5:$F189,B$3) -> 0 | C18: =COUNTIFS('YouTube Feature List'!$B5:$B189,$A18,'YouTube Feature List'!$F5:$F189,C$3) -> 0 | D18: =COUNTIFS('YouTube Feature List'!$B5:$B189,$A18,'YouTube Feature List'!$F5:$F189,D$3) -> 0 | E18: =COUNTIFS('YouTube Feature List'!$B5:$B189,$A18,'YouTube Feature List'!$F5:$F189,E$3) -> 0 | F18: =COUNTIFS('YouTube Feature List'!$B5:$B189,$A18,'YouTube Feature List'!$F5:$F189,F$3) -> 0 | G18: =COUNTIF('YouTube Feature List'!$B5:$B189,$A18) -> 4
A19: 16. Premium / Paid Bundled Services | B19: =COUNTIFS('YouTube Feature List'!$B5:$B189,$A19,'YouTube Feature List'!$F5:$F189,B$3) -> 0 | C19: =COUNTIFS('YouTube Feature List'!$B5:$B189,$A19,'YouTube Feature List'!$F5:$F189,C$3) -> 0 | D19: =COUNTIFS('YouTube Feature List'!$B5:$B189,$A19,'YouTube Feature List'!$F5:$F189,D$3) -> 0 | E19: =COUNTIFS('YouTube Feature List'!$B5:$B189,$A19,'YouTube Feature List'!$F5:$F189,E$3) -> 0 | F19: =COUNTIFS('YouTube Feature List'!$B5:$B189,$A19,'YouTube Feature List'!$F5:$F189,F$3) -> 0 | G19: =COUNTIF('YouTube Feature List'!$B5:$B189,$A19) -> 8
A20: 17. AI & Emerging Creation Tools | B20: =COUNTIFS('YouTube Feature List'!$B5:$B189,$A20,'YouTube Feature List'!$F5:$F189,B$3) -> 0 | C20: =COUNTIFS('YouTube Feature List'!$B5:$B189,$A20,'YouTube Feature List'!$F5:$F189,C$3) -> 0 | D20: =COUNTIFS('YouTube Feature List'!$B5:$B189,$A20,'YouTube Feature List'!$F5:$F189,D$3) -> 0 | E20: =COUNTIFS('YouTube Feature List'!$B5:$B189,$A20,'YouTube Feature List'!$F5:$F189,E$3) -> 0 | F20: =COUNTIFS('YouTube Feature List'!$B5:$B189,$A20,'YouTube Feature List'!$F5:$F189,F$3) -> 0 | G20: =COUNTIF('YouTube Feature List'!$B5:$B189,$A20) -> 5
A21: 18. Discontinued / Historical (misc.) | B21: =COUNTIFS('YouTube Feature List'!$B5:$B189,$A21,'YouTube Feature List'!$F5:$F189,B$3) -> 0 | C21: =COUNTIFS('YouTube Feature List'!$B5:$B189,$A21,'YouTube Feature List'!$F5:$F189,C$3) -> 0 | D21: =COUNTIFS('YouTube Feature List'!$B5:$B189,$A21,'YouTube Feature List'!$F5:$F189,D$3) -> 0 | E21: =COUNTIFS('YouTube Feature List'!$B5:$B189,$A21,'YouTube Feature List'!$F5:$F189,E$3) -> 0 | F21: =COUNTIFS('YouTube Feature List'!$B5:$B189,$A21,'YouTube Feature List'!$F5:$F189,F$3) -> 0 | G21: =COUNTIF('YouTube Feature List'!$B5:$B189,$A21) -> 5
A22: TOTAL | B22: =SUM(B4:B21) -> 0 | C22: =SUM(C4:C21) -> 0 | D22: =SUM(D4:D21) -> 0 | E22: =SUM(E4:E21) -> 0 | F22: =SUM(F4:F21) -> 0 | G22: =SUM(G4:G21) -> 185
